Workbook

Sheet Dashboard
B2: T-Mobile 3-Statement Model & DCF Valuation
B4: 5-Year Projection (FY2026E–FY2030E) | An independent valuation built from public filings | Prepared by Brett Tierce
B5: Valuation date: 10/13/2026 | $ in millions unless noted | All figures are live links to the model tabs | H5: Jump to: | J5: 3-Statement Model | L5: DCF Model
B7: IMPLIED SHARE PRICE | D7: CURRENT SHARE PRICE | F7: IMPLIED UPSIDE / (DOWNSIDE) | H7: ENTERPRISE VALUE | J7: WACC | L7: IMPLIED EQUITY VALUE
B8: ='T-Mobile DCF Model'!C38 -> 190.23361 | D8: ='T-Mobile DCF Model'!C39 -> 154.06 | F8: ='T-Mobile DCF Model'!C40 -> 0.23480206 | H8: ='T-Mobile DCF Model'!C32 -> 296097.32 | J8: ='T-Mobile DCF Model'!C45 -> 0.058585836 | L8: ='T-Mobile DCF Model'!C36 -> 209611.32
B9: ="DCF base case | "&TEXT('T-Mobile DCF Model'!C37,"#,##0")&"mm shares" -> DCF base case | 1,102mm shares | D9: ="Market cap $"&TEXT('T-Mobile DCF Model'!F32/1000,"#,##0.0")&"bn | 10/13/2026" -> Market cap $169.8bn | 10/13/2026 | F9: ="Implied value vs. current price" -> Implied value vs. current price | H9: ="Implied "&TEXT('T-Mobile DCF Model'!C32/'T-Mobile DCF Model'!C7,"0.0")&"x FY25A EBITDA" -> Implied 9.3x FY25A EBITDA | J9: ="Exit multiple "&TEXT('T-Mobile DCF Model'!C43,"0.0")&"x EBITDA" -> Exit multiple 7.0x EBITDA | L9: ="Net debt $"&TEXT(-('T-Mobile DCF Model'!C33+'T-Mobile DCF Model'!C34)/1000,"0.0")&"bn (FY25A)" -> Net debt $86.5bn (FY25A)
B11: FY25A REVENUE | D11: REVENUE CAGR (FY25A–FY30E) | F11: FY25A EBITDA MARGIN | H11: FY30E NET INCOME | J11: NET DEBT / EBITDA (FY25A) | L11: FY30E UNLEVERED FCF
B12: ='T-Mobile 3 Statement Model'!E4 -> 88309 | D12: =('T-Mobile 3 Statement Model'!J4/'T-Mobile 3 Statement Model'!E4)^(1/5)-1 -> 0.060527121 | F12: ='T-Mobile DCF Model'!C8 -> 0.35995199 | H12: ='T-Mobile 3 Statement Model'!J14 -> 15324.411 | J12: =F41 -> 2.7207978 | L12: ='T-Mobile DCF Model'!H19 -> 19707.042
B13: =TEXT('T-Mobile 3 Statement Model'!E17,"+0.0%;-0.0%")&" year over year" -> +8.5% year over year | D13: ="FY30E revenue $"&TEXT('T-Mobile 3 Statement Model'!J4/1000,"0.0")&"bn" -> FY30E revenue $118.5bn | F13: ="FY30E: "&TEXT('T-Mobile DCF Model'!H8,"0.0%") -> FY30E: 35.6% | H13: ="FY25A: $"&TEXT('T-Mobile 3 Statement Model'!E14/1000,"0.0")&"bn" -> FY25A: $11.0bn | J13: ="FY30E: "&TEXT(K41,"0.0")&"x" -> FY30E: 2.3x | L13: ="UFCF CAGR FY26E–30E: "&TEXT(('T-Mobile DCF Model'!H19/'T-Mobile DCF Model'!D19)^(1/4)-1,"0.0%") -> UFCF CAGR FY26E–30E: 6.1%
B15: EXECUTIVE SUMMARY & INVESTMENT THESIS | H15: KEY MODEL ASSUMPTIONS
B16: ="Base-case DCF points to "&TEXT(ABS(F8),"0%")&IF(F88>=0," upside"," downside")&" versus the current share price" -> Base-case DCF points to 23% upside versus the current share price | H16: Revenue growth (FY26E–FY30E) | L16: ='T-Mobile 3 Statement Model'!F17 -> 0.060527121
B17: Valuation | C17: ="The DCF model suggests $"&TEXT(B8,"0.00")&" per share vs. $"&TEXT(D8,"0.00")&" today, using a "&TEXT('T-Mobile DCF Model'!C45,"0.0%")&" WACC and a "&TEXT('T-Mobile DCF Model'!C43,"0.0")&"x terminal multiple on a five-year unlevered cash flow forecast." -> The DCF model suggests $190.23 per share vs. $154.06 today, using a 5.9% WACC and a 7.0x terminal multiple on a five-year unlevered cash flow forecast. | H17: Gross margin | L17: ='T-Mobile 3 Statement Model'!F18 -> 0.6267691
H18: EBITDA margin | L18: ='T-Mobile DCF Model'!D8 -> 0.35624305
B19: Margin of safety | C19: ="Across the "&COUNT(I47:M51)&"-case sensitivity grid (WACC "&TEXT(MIN(H47:H51),"0.0%")&"–"&TEXT(MAX(H47:H51),"0.0%")&", exit multiple "&TEXT(MIN(I46:M46),"0.0")&"x–"&TEXT(MAX(I46:M46),"0.0")&"x), suggested value spans $"&TEXT(K54,"0")&"–$"&TEXT(M54,"0")&"" -> Across the 25-case sensitivity grid (WACC 4.5%–6.5%, exit multiple 6.0x–8.0x), suggested value spans $155–$237 | H19: Effective tax rate | L19: ='T-Mobile 3 Statement Model'!F20 -> 0.23447166
H20: Net new debt issued ($mm / yr) | L20: ='T-Mobile 3 Statement Model'!F38 -> 5000
B21: Growth & margins | C21: ="Revenue is forecast to compound at "&TEXT(D12,"0.0%")&" a year to $"&TEXT('T-Mobile 3 Statement Model'!J4/1000,"0.0")&"bn by FY"&'T-Mobile 3 Statement Model'!J3&"E, with EBITDA margin near "&TEXT(F12,"0.0%")&" and net income rising from $"&TEXT(F37/1000,"0.0")&"bn to $"&TEXT(K37/1000,"0.0")&"bn." -> Revenue is forecast to compound at 6.1% a year to $118.5bn by FY2030E, with EBITDA margin near 36.0% and net income rising from $11.0bn to $15.3bn. | H21: Share repurchases ($mm / yr) | L21: =-'T-Mobile 3 Statement Model'!F90 -> 9974
H22: Risk-free rate | L22: ='T-Mobile DCF Model'!F42 -> 0.043
B23: Cash returns | C23: ="Free cash flow after capex of $"&TEXT(('T-Mobile 3 Statement Model'!F115+'T-Mobile 3 Statement Model'!F119)/1000,"0.0")&"bn in FY"&'T-Mobile 3 Statement Model'!F3&"E compares with $"&TEXT(('T-Mobile 3 Statement Model'!F128+'T-Mobile 3 Statement Model'!F130)/-1000,"0.0")&"bn of dividends and buybacks, "&IF(D115>D112,"so shareholder returns are partly debt-funded","so shareholder returns are covered by free cash flow")&" ($"&TEXT('T-Mobile 3 Statement Model'!F121/1000,"0.0")&"bn of net new debt per year)." -> Free cash flow after capex of $12.7bn in FY2026E compares with $14.5bn of dividends and buybacks, so shareholder returns are covered by free cash flow ($5.0bn of net new debt per year). | H23: Equity beta | L23: ='T-Mobile DCF Model'!F43 -> 0.63
H24: Equity risk premium | L24: ='T-Mobile DCF Model'!F44 -> 0.0475
B25: Key risks | C25: ="Terminal value is "&TEXT(F47/F48,"0%")&" of enterprise value, so results hinge on the exit multiple and WACC. Net debt/EBITDA is "&TEXT(F41,"0.0")&"x today and "&TEXT(K41,"0.0")&"x by FY"&'T-Mobile 3 Statement Model'!J3&"E; revenue growth is held flat at "&TEXT('T-Mobile 3 Statement Model'!F17,"0.0%")&" a year." -> Terminal value is 75% of enterprise value, so results hinge on the exit multiple and WACC. Net debt/EBITDA is 2.7x today and 2.3x by FY2030E; revenue growth is held flat at 6.1% a year. | H25: Cost of equity | L25: ='T-Mobile DCF Model'!F45 -> 0.072925
H26: After-tax cost of debt | L26: ='T-Mobile DCF Model'!F40 -> 0.03215219
B27: Model integrity | C27: {="Integrated income statement, balance sheet and cash flow built from 10-K filings (FY"&'T-Mobile 3 Statement Model'!C3&"A–FY"&'T-Mobile 3 Statement Model'!E3&"A); "&IF(SUMPRODUCT(ABS('T-Mobile 3 Statement Model'!C80:J80))<1,"the balance sheet balances in every period.","CHECK: balance sheet does not balance in every period.")} -> Integrated income statement, balance sheet and cash flow built from 10-K filings (FY2023A–FY2025A); the balance sheet balances in every period. | H27: WACC | L27: ='T-Mobile DCF Model'!C45 -> 0.058585836
H28: Terminal EV / EBITDA multiple | L28: ='T-Mobile DCF Model'!C43 -> 7
B30: Financial Summary ($mm) | D30: ="FY"&'T-Mobile 3 Statement Model'!C3&"A" -> FY2023A | E30: ="FY"&'T-Mobile 3 Statement Model'!D3&"A" -> FY2024A | F30: ="FY"&'T-Mobile 3 Statement Model'!E3&"A" -> FY2025A | G30: ="FY"&'T-Mobile 3 Statement Model'!F3&"A" -> FY2026A | H30: ="FY"&'T-Mobile 3 Statement Model'!G3&"A" -> FY2027A | I30: ="FY"&'T-Mobile 3 Statement Model'!H3&"A" -> FY2028A | J30: ="FY"&'T-Mobile 3 Statement Model'!I3&"A" -> FY2029A | K30: ="FY"&'T-Mobile 3 Statement Model'!J3&"A" -> FY2030A | L30: CAGR / Avg.*
B31: Revenue | D31: ='T-Mobile 3 Statement Model'!C4 -> 78558 | E31: ='T-Mobile 3 Statement Model'!D4 -> 81400 | F31: ='T-Mobile 3 Statement Model'!E4 -> 88309 | G31: ='T-Mobile 3 Statement Model'!F4 -> 93654.09 | H31: ='T-Mobile 3 Statement Model'!G4 -> 99322.702 | I31: ='T-Mobile 3 Statement Model'!H4 -> 105334.42 | J31: ='T-Mobile 3 Statement Model'!I4 -> 111710.01 | K31: ='T-Mobile 3 Statement Model'!J4 -> 118471.49 | L31: =(K31/F31)^(1/5)-1 -> 0.060527121
B32: % growth | D32: – | E32: ='T-Mobile 3 Statement Model'!D17 -> 0.036177092 | F32: ='T-Mobile 3 Statement Model'!E17 -> 0.08487715 | G32: ='T-Mobile 3 Statement Model'!F17 -> 0.060527121 | H32: ='T-Mobile 3 Statement Model'!G17 -> 0.060527121 | I32: ='T-Mobile 3 Statement Model'!H17 -> 0.060527121 | J32: ='T-Mobile 3 Statement Model'!I17 -> 0.060527121 | K32: ='T-Mobile 3 Statement Model'!J17 -> 0.060527121 | L32: =AVERAGE(G32:K32) -> 0.060527121
B33: EBITDA | D33: ='T-Mobile 3 Statement Model'!C7-'T-Mobile 3 Statement Model'!C23 -> 27084 | E33: ='T-Mobile 3 Statement Model'!D7-'T-Mobile 3 Statement Model'!D23 -> 30929 | F33: ='T-Mobile 3 Statement Model'!E7-'T-Mobile 3 Statement Model'!E23 -> 31787 | G33: ='T-Mobile 3 Statement Model'!F7-'T-Mobile 3 Statement Model'!F23 -> 33363.619 | H33: ='T-Mobile 3 Statement Model'!G7-'T-Mobile 3 Statement Model'!G23 -> 35383.022 | I33: ='T-Mobile 3 Statement Model'!H7-'T-Mobile 3 Statement Model'!H23 -> 37524.655 | J33: ='T-Mobile 3 Statement Model'!I7-'T-Mobile 3 Statement Model'!I23 -> 39795.914 | K33: ='T-Mobile 3 Statement Model'!J7-'T-Mobile 3 Statement Model'!J23 -> 42204.646 | L33: =(K33/F33)^(1/5)-1 -> 0.058332528
B34: % margin | D34: =D33/D31 -> 0.34476438 | E34: =E33/E31 -> 0.37996314 | F34: =F33/F31 -> 0.35995199 | G34: =G33/G31 -> 0.35624305 | H34: =H33/H31 -> 0.35624305 | I34: =I33/I31 -> 0.35624305 | J34: =J33/J31 -> 0.35624305 | K34: =K33/K31 -> 0.35624305 | L34: =AVERAGE(G34:K34) -> 0.35624305
B35: EBIT (operating income) | D35: ='T-Mobile 3 Statement Model'!C7 -> 14266 | E35: ='T-Mobile 3 Statement Model'!D7 -> 18010 | F35: ='T-Mobile 3 Statement Model'!E7 -> 18279 | G35: ='T-Mobile 3 Statement Model'!F7 -> 19038.018 | H35: ='T-Mobile 3 Statement Model'!G7 -> 20190.335 | I35: ='T-Mobile 3 Statement Model'!H7 -> 21412.397 | J35: ='T-Mobile 3 Statement Model'!I7 -> 22708.428 | K35: ='T-Mobile 3 Statement Model'!J7 -> 24082.904 | L35: =(K35/F35)^(1/5)-1 -> 0.05669897
B36: % margin | D36: =D35/D31 -> 0.18159831 | E36: =E35/E31 -> 0.22125307 | F36: =F35/F31 -> 0.2069891 | G36: =G35/G31 -> 0.20328016 | H36: =H35/H31 -> 0.20328016 | I36: =I35/I31 -> 0.20328016 | J36: =J35/J31 -> 0.20328016 | K36: =K35/K31 -> 0.20328016 | L36: =AVERAGE(G36:K36) -> 0.20328016
B37: Net income | D37: ='T-Mobile 3 Statement Model'!C14 -> 8317 | E37: ='T-Mobile 3 Statement Model'!D14 -> 11339 | F37: ='T-Mobile 3 Statement Model'!E14 -> 10992 | G37: ='T-Mobile 3 Statement Model'!F14 -> 11855.565 | H37: ='T-Mobile 3 Statement Model'!G14 -> 12619.611 | I37: ='T-Mobile 3 Statement Model'!H14 -> 13450.963 | J37: ='T-Mobile 3 Statement Model'!I14 -> 14351.089 | K37: ='T-Mobile 3 Statement Model'!J14 -> 15324.411 | L37: =(K37/F37)^(1/5)-1 -> 0.068713794
B38: % margin | D38: =D37/D31 -> 0.10587082 | E38: =E37/E31 -> 0.13929975 | F38: =F37/F31 -> 0.12447202 | G38: =G37/G31 -> 0.12658886 | H38: =H37/H31 -> 0.12705666 | I38: =I37/I31 -> 0.1276977 | J38: =J37/J31 -> 0.12846735 | K38: =K37/K31 -> 0.12935104 | L38: =AVERAGE(G38:K38) -> 0.12783232
B39: Unlevered free cash flow | D39: – | E39: – | F39: ='T-Mobile DCF Model'!C19 -> 12381.093 | G39: ='T-Mobile DCF Model'!D19 -> 15579.775 | H39: ='T-Mobile DCF Model'!E19 -> 16521.752 | I39: ='T-Mobile DCF Model'!F19 -> 17521.766 | J39: ='T-Mobile DCF Model'!G19 -> 18582.308 | K39: ='T-Mobile DCF Model'!H19 -> 19707.042 | L39: =(K39/F39)^(1/5)-1 -> 0.097419048
B40: Net debt | D40: ='T-Mobile 3 Statement Model'!C59+'T-Mobile 3 Statement Model'!C65+'T-Mobile 3 Statement Model'!C66+'T-Mobile 3 Statement Model'!C67-'T-Mobile 3 Statement Model'!C42 -> 76156 | E40: ='T-Mobile 3 Statement Model'!D59+'T-Mobile 3 Statement Model'!D65+'T-Mobile 3 Statement Model'!D66+'T-Mobile 3 Statement Model'!D67-'T-Mobile 3 Statement Model'!D42 -> 78846 | F40: ='T-Mobile 3 Statement Model'!E59+'T-Mobile 3 Statement Model'!E65+'T-Mobile 3 Statement Model'!E66+'T-Mobile 3 Statement Model'!E67-'T-Mobile 3 Statement Model'!E42 -> 86486 | G40: ='T-Mobile 3 Statement Model'!F59+'T-Mobile 3 Statement Model'!F65+'T-Mobile 3 Statement Model'!F66+'T-Mobile 3 Statement Model'!F67-'T-Mobile 3 Statement Model'!F42 -> 89627.751 | H40: ='T-Mobile 3 Statement Model'!G59+'T-Mobile 3 Statement Model'!G65+'T-Mobile 3 Statement Model'!G66+'T-Mobile 3 Statement Model'!G67-'T-Mobile 3 Statement Model'!G42 -> 92163.686 | I40: ='T-Mobile 3 Statement Model'!H59+'T-Mobile 3 Statement Model'!H65+'T-Mobile 3 Statement Model'!H66+'T-Mobile 3 Statement Model'!H67-'T-Mobile 3 Statement Model'!H42 -> 94170.614 | J40: ='T-Mobile 3 Statement Model'!I59+'T-Mobile 3 Statement Model'!I65+'T-Mobile 3 Statement Model'!I66+'T-Mobile 3 Statement Model'!I67-'T-Mobile 3 Statement Model'!I42 -> 95605.179 | K40: ='T-Mobile 3 Statement Model'!J59+'T-Mobile 3 Statement Model'!J65+'T-Mobile 3 Statement Model'!J66+'T-Mobile 3 Statement Model'!J67-'T-Mobile 3 Statement Model'!J42 -> 96421.244 | L40: =(K40/F40)^(1/5)-1 -> 0.021987029
B41: Net debt / EBITDA | D41: =D40/D33 -> 2.8118446 | E41: =E40/E33 -> 2.549258 | F41: =F40/F33 -> 2.7207978 | G41: =G40/G33 -> 2.6863918 | H41: =H40/H33 -> 2.6047432 | I41: =I40/I33 -> 2.5095664 | J41: =J40/J33 -> 2.4023868 | K41: =K40/K33 -> 2.2846121 | L41: –
B42: EBIT / net interest expense | D42: =D35/-'T-Mobile 3 Statement Model'!C10 -> 4.2776612 | E42: =E35/-'T-Mobile 3 Statement Model'!D10 -> 5.2799765 | F42: =F35/-'T-Mobile 3 Statement Model'!E10 -> 4.8434022 | G42: =G35/-'T-Mobile 3 Statement Model'!F10 -> 5.3609434 | H42: =H35/-'T-Mobile 3 Statement Model'!G10 -> 5.4487528 | I42: =I35/-'T-Mobile 3 Statement Model'!H10 -> 5.5738596 | J42: =J35/-'T-Mobile 3 Statement Model'!I10 -> 5.7318716 | K42: =K35/-'T-Mobile 3 Statement Model'!J10 -> 5.9247169 | L42: –
B44: VALUATION
B45: DCF Valuation Bridge ($mm, except per share) | H45: Sensitivity: Implied Share Price ($)
B46: PV of explicit-period UFCF | F46: ='T-Mobile DCF Model'!C30 -> 73854.414 | H46: WACC ↓ / Multiple → | I46: ='T-Mobile DCF Model'!C49 -> 6 | J46: ='T-Mobile DCF Model'!D49 -> 6.5 | K46: ='T-Mobile DCF Model'!E49 -> 7 | L46: ='T-Mobile DCF Model'!F49 -> 7.5 | M46: ='T-Mobile DCF Model'!G49 -> 8
B47: PV of terminal value | F47: ='T-Mobile DCF Model'!C31 -> 222242.91 | H47: ='T-Mobile DCF Model'!B50 -> 0.045 | I47: ='T-Mobile DCF Model'!C50 -> 175.61708 | J47: ='T-Mobile DCF Model'!D50 -> 190.98522 | K47: ='T-Mobile DCF Model'!E50 -> 206.35336 | L47: ='T-Mobile DCF Model'!F50 -> 221.7215 | M47: ='T-Mobile DCF Model'!G50 -> 237.08964
...

Sheet T-Mobile 3 Statement Model
B2: Income Statement | C2: Actuals | F2: Projections
B3: $ in millions | C3: 2023 | D3: 2024 | E3: 2025 | F3: 2026 | G3: 2027 | H3: 2028 | I3: 2029 | J3: 2030
B4: Revenue | C4: 78558 | D4: 81400 | E4: 88309 | F4: =E4*(1+F17) -> 93654.09 | G4: =F4*(1+G17) -> 99322.702 | H4: =G4*(1+H17) -> 105334.42 | I4: =H4*(1+I17) -> 111710.01 | J4: =I4*(1+J17) -> 118471.49
B5: Operating Expenses | C5: -34104 | D5: -33737 | E5: -37256 | F5: =-F4*F19 -> -39661.471 | G5: =-G4*G19 -> -42062.066 | H5: =-H4*H19 -> -44607.961 | I5: =-I4*I19 -> -47307.953 | J5: =-J4*J19 -> -50171.367
B6: Cost of Sales (COGS) | C6: -30188 | D6: -29653 | E6: -32774 | F6: =-F4*(1-F18) -> -34954.6 | G6: =-G4*(1-G18) -> -37070.302 | H6: =-H4*(1-H18) -> -39314.06 | I6: =-I4*(1-I18) -> -41693.627 | J6: =-J4*(1-J18) -> -44217.222
B7: Operating Income (EBIT) | C7: =SUM(C4:C6) -> 14266 | D7: =SUM(D4:D6) -> 18010 | E7: =SUM(E4:E6) -> 18279 | F7: =SUM(F4:F6) -> 19038.018 | G7: =SUM(G4:G6) -> 20190.335 | H7: =SUM(H4:H6) -> 21412.397 | I7: =SUM(I4:I6) -> 22708.428 | J7: =SUM(J4:J6) -> 24082.904
B9: Net Other (expense) Income | C9: 68 | D9: 113 | E9: -224 | F9: 0 | G9: 0 | H9: 0 | I9: 0 | J9: 0
B10: Net Interest Expense | C10: -3335 | D10: -3411 | E10: -3774 | F10: =-F37*(E59+E65+E66)+F36*E42 -> -3551.244 | G10: =-G37*(F59+F65+F66)+G36*F42 -> -3705.4965 | H10: =-H37*(G59+G65+G66)+H36*G42 -> -3841.5746 | I10: =-I37*(H59+H65+H66)+I36*H42 -> -3961.7824 | J10: =-J37*(I59+I65+I66)+J36*I42 -> -4064.8194
B11: Income Before Taxes (EBT) | C11: =SUM(C7,C9:C10) -> 10999 | D11: =SUM(D7,D9:D10) -> 14712 | E11: =SUM(E7,E9:E10) -> 14281 | F11: =SUM(F7,F9:F10) -> 15486.774 | G11: =SUM(G7,G9:G10) -> 16484.838 | H11: =SUM(H7,H9:H10) -> 17570.823 | I11: =SUM(I7,I9:I10) -> 18746.646 | J11: =SUM(J7,J9:J10) -> 20018.085
B13: Income Tax Expense | C13: -2682 | D13: -3373 | E13: -3289 | F13: =-F20*F11 -> -3631.2096 | G13: =-G20*G11 -> -3865.2273 | H13: =-H20*H11 -> -4119.86 | I13: =-I20*I11 -> -4395.5571 | J13: =-J20*J11 -> -4693.6735
B14: Net Income | C14: =SUM(C11,C13) -> 8317 | D14: =SUM(D11,D13) -> 11339 | E14: =SUM(E11,E13) -> 10992 | F14: =SUM(F11,F13) -> 11855.565 | G14: =SUM(G11,G13) -> 12619.611 | H14: =SUM(H11,H13) -> 13450.963 | I14: =SUM(I11,I13) -> 14351.089 | J14: =SUM(J11,J13) -> 15324.411
B16: Margins / Growth Rates
B17: Revenue Growth Rate | D17: =D4/C4-1 -> 0.036177092 | E17: =E4/D4-1 -> 0.08487715 | F17: =AVERAGE(D17:E17) -> 0.060527121 | G17: =F17 -> 0.060527121 | H17: =G17 -> 0.060527121 | I17: =H17 -> 0.060527121 | J17: =I17 -> 0.060527121
B18: Gross Profit Margin | C18: =1+(C6/C4) -> 0.61572341 | D18: =1+(D6/D4) -> 0.63571253 | E18: =1+(E6/E4) -> 0.62887135 | F18: =AVERAGE(C18:E18) -> 0.6267691 | G18: =F18 -> 0.6267691 | H18: =G18 -> 0.6267691 | I18: =H18 -> 0.6267691 | J18: =I18 -> 0.6267691
B19: Operating Expenses as % of Revenue | C19: =-C5/C4 -> 0.43412511 | D19: =-D5/D4 -> 0.41445946 | E19: =-E5/E4 -> 0.42188225 | F19: =AVERAGE(C19:E19) -> 0.42348894 | G19: =F19 -> 0.42348894 | H19: =G19 -> 0.42348894 | I19: =H19 -> 0.42348894 | J19: =I19 -> 0.42348894
B20: Tax Rate | C20: =-C13/C11 -> 0.24384035 | D20: =-D13/D11 -> 0.22926862 | E20: =-E13/E11 -> 0.230306 | F20: =AVERAGE(C20:E20) -> 0.23447166 | G20: =F20 -> 0.23447166 | H20: =G20 -> 0.23447166 | I20: =H20 -> 0.23447166 | J20: =I20 -> 0.23447166
B21: COGS Growth Rate | F21: =F6/E6-1 -> 0.066534457 | G21: =G6/F6-1 -> 0.060527121 | H21: =H6/G6-1 -> 0.060527121 | I21: =I6/H6-1 -> 0.060527121 | J21: =J6/I6-1 -> 0.060527121
B23: Memo: Total D&A | C23: -12818 | D23: -12919 | E23: -13508 | F23: =-(E23*(1+F17))*-1 -> -14325.6 | G23: =-(F23*(1+G17))*-1 -> -15192.688 | H23: =-(G23*(1+H17))*-1 -> -16112.257 | I23: =-(H23*(1+I17))*-1 -> -17087.486 | J23: =-(I23*(1+J17))*-1 -> -18121.742
B24: Memo: Depreciation OPEX & COGS | C24: =C23-C28 -> -11930 | D24: =D23-D28 -> -12062 | E24: =E23-E28 -> -12533 | F24: =F23-F28 -> -13291.586 | G24: =G23-G28 -> -14096.088 | H24: =H23-H28 -> -14949.283 | I24: =I23-I28 -> -15854.121 | J24: =J23-J28 -> -16813.725
B25: Memo: Capital Expenditures | C25: -9801 | D25: -8840 | E25: -9955 | F25: =E25*(1+F17) -> -10557.547 | G25: =F25*(1+G17) -> -11196.565 | H25: =G25*(1+H17) -> -11874.261 | I25: =H25*(1+I17) -> -12592.976 | J25: =I25*(1+J17) -> -13355.193
B26: Memo: Finance Lease Right-of-Use Obtained | C26: -1224 | D26: -1222 | E26: -1232 | F26: -1200 | G26: =F26 -> -1200 | H26: =G26 -> -1200 | I26: =H26 -> -1200 | J26: =I26 -> -1200
B28: Memo: Amortization Intangibles | C28: -888 | D28: -857 | E28: -975 | F28: =-(E28*(1+F17)*-1) -> -1034.0139 | G28: =-(F28*(1+G17)*-1) -> -1096.5998 | H28: =-(G28*(1+H17)*-1) -> -1162.9739 | I28: =-(H28*(1+I17)*-1) -> -1233.3653 | J28: =-(I28*(1+J17)*-1) -> -1308.0174
B29: Memo: Purchases of Intangibles | C29: -1010 | D29: -3471 | E29: -2568 | F29: =E29*(1+F17) -> -2723.4336 | G29: =F29*(1+G17) -> -2888.2752 | H29: =G29*(1+H17) -> -3063.0942 | I29: =H29*(1+I17) -> -3248.4945 | J29: =I29*(1+J17) -> -3445.1165
B31: Operating Lease Assets as % of Operating Expenses | D31: =D51/-SUM(D5:D6) -> 0.40066257 | E31: =E51/-SUM(E5:E6) -> 0.36687134 | F31: =E31 -> 0.36687134 | G31: =F31 -> 0.36687134 | H31: =G31 -> 0.36687134 | I31: =H31 -> 0.36687134 | J31: =I31 -> 0.36687134
B32: Change in Operating Lease Assets | D32: =D51-C51 -> -1737 | E32: =E51-D51 -> 294 | F32: =F51-E51 -> 1682.4981 | G32: =G51-F51 -> 1656.8996 | H32: =H51-G51 -> 1757.1869 | I32: =I51-H51 -> 1863.5444 | J32: =J51-I51 -> 1976.3394
B34: Memo: Other Non-Current Assets as % of Revenue | C34: =(C53/C4) -> 0.07982637 | D34: =(D53/D4) -> 0.08027027 | E34: =(E53/E4) -> 0.14084635 | F34: =E34 -> 0.14084635 | G34: =F34 -> 0.14084635 | H34: =G34 -> 0.14084635 | I34: =H34 -> 0.14084635 | J34: =I34 -> 0.14084635
B35: Memo: Dividend Payout Ratio (% of Net Income) | C35: =-C95/C14 -> 0.089816039 | D35: =-D95/D14 -> 0.37939854 | E35: =-E95/E14 -> 0.38573508 | F35: =E35 -> 0.38573508 | G35: =F35 -> 0.38573508 | H35: =G35 -> 0.38573508 | I35: =H35 -> 0.38573508 | J35: =I35 -> 0.38573508
B36: Memo: % Interest Earned on Cash | F36: 0.03 | G36: 0.03 | H36: 0.03 | I36: 0.03 | J36: 0.03
B37: Memo: % Interest Rate on Debt | F37: 0.042 | G37: 0.042 | H37: 0.042 | I37: 0.042 | J37: 0.042
B38: Memo: Net New Long-Term Debt Issued | C38: 3395 | D38: 3514 | E38: 5811 | F38: 5000 | G38: =F38 -> 5000 | H38: =G38 -> 5000 | I38: =H38 -> 5000 | J38: =I38 -> 5000
B40: Balance Sheet | C40: Actuals | F40: Projections
B41: $ in millions | C41: 2023 | D41: 2024 | E41: 2025 | F41: 2026 | G41: 2027 | H41: 2028 | I41: 2029 | J41: 2030
B42: Cash & Cash Equivalents | C42: 5135 | D42: 5409 | E42: 5598 | F42: =E42+F133 -> 7456.249 | G42: =F42+G133 -> 9920.3141 | H42: =G42+H133 -> 12913.386 | I42: =H42+I133 -> 16478.821 | J42: =I42+J133 -> 20662.756
B43: Accounts Receivable | C43: 4692 | D43: 4276 | E43: 4874 | F43: =E43*(1+F17) -> 5169.0092 | G43: =F43*(1+G17) -> 5481.8744 | H43: =G43*(1+H17) -> 5813.6765 | I43: =H43*(1+I17) -> 6165.5616 | J43: =I43*(1+J17) -> 6538.7453
B44: Equipment Installment Plan Receivables | C44: 4456 | D44: 4379 | E44: 4997 | F44: =E44*(1+F17) -> 5299.454 | G44: =F44*(1+G17) -> 5620.2147 | H44: =G44*(1+H17) -> 5960.3901 | I44: =H44*(1+I17) -> 6321.1554 | J44: =I44*(1+J17) -> 6703.7567
B45: Inventory | C45: 1678 | D45: 1607 | E45: 2405 | F45: =E45*(1+F21) -> 2565.0154 | G45: =F45*(1+G21) -> 2720.2684 | H45: =G45*(1+H21) -> 2884.9184 | I45: =H45*(1+I21) -> 3059.5342 | J45: =I45*(1+J21) -> 3244.719
B46: Prepaid Expenses | C46: 702 | D46: 880 | E46: 1215 | F46: =E46*(1+F17) -> 1288.5405 | G46: =F46*(1+G17) -> 1366.5321 | H46: =G46*(1+H17) -> 1449.2443 | I46: =H46*(1+I17) -> 1536.9629 | J46: =I46*(1+J17) -> 1629.9909
B47: Other Current Assets | C47: 2352 | D47: 1853 | E47: 5372 | F47: =E47*(1+$F$17) -> 5697.1517 | G47: =F47*(1+$F$17) -> 6041.9839 | H47: =G47*(1+$F$17) -> 6407.6878 | I47: =H47*(1+$F$17) -> 6795.5267 | J47: =I47*(1+$F$17) -> 7206.8403
B48: Total Current Assets | C48: =SUM(C42:C47) -> 19015 | D48: =SUM(D42:D47) -> 18404 | E48: =SUM(E42:E47) -> 24461 | F48: =SUM(F42:F47) -> 27475.42 | G48: =SUM(G42:G47) -> 31151.188 | H48: =SUM(H42:H47) -> 35429.303 | I48: =SUM(I42:I47) -> 40357.561 | J48: =SUM(J42:J47) -> 45986.808
B50: Property Plant & Equipment | C50: 43702 | D50: 41624 | E50: 41093 | F50: =E50-F25+F24-F26 -> 39558.961 | G50: =F50-G25+G24-G26 -> 37859.439 | H50: =G50-H25+H24-H26 -> 35984.416 | I50: =H50-I25+I24-I26 -> 33923.272 | J50: =I50-J25+J24-J26 -> 31664.74
...

Sheet T-Mobile DCF Model
B2: Year | C2: 0 | D2: 1 | E2: 2 | F2: 3 | G2: 4 | H2: 5
B3: Income Statement ($ in millions)
B4: Revenue | C4: ='T-Mobile 3 Statement Model'!E4 -> 88309 | D4: ='T-Mobile 3 Statement Model'!F4 -> 93654.09 | E4: ='T-Mobile 3 Statement Model'!G4 -> 99322.702 | F4: ='T-Mobile 3 Statement Model'!H4 -> 105334.42 | G4: ='T-Mobile 3 Statement Model'!I4 -> 111710.01 | H4: ='T-Mobile 3 Statement Model'!J4 -> 118471.49
B5: % Growth | C5: ='T-Mobile 3 Statement Model'!E17 -> 0.08487715 | D5: ='T-Mobile 3 Statement Model'!F17 -> 0.060527121 | E5: ='T-Mobile 3 Statement Model'!G17 -> 0.060527121 | F5: ='T-Mobile 3 Statement Model'!H17 -> 0.060527121 | G5: ='T-Mobile 3 Statement Model'!I17 -> 0.060527121 | H5: ='T-Mobile 3 Statement Model'!J17 -> 0.060527121
B7: EBITDA | C7: =C11-C10 -> 31787 | D7: =D11-D10 -> 33363.619 | E7: =E11-E10 -> 35383.022 | F7: =F11-F10 -> 37524.655 | G7: =G11-G10 -> 39795.914 | H7: =H11-H10 -> 42204.646
B8: % Margin | C8: =C7/'T-Mobile 3 Statement Model'!E4 -> 0.35995199 | D8: =D7/'T-Mobile 3 Statement Model'!F4 -> 0.35624305 | E8: =E7/'T-Mobile 3 Statement Model'!G4 -> 0.35624305 | F8: =F7/'T-Mobile 3 Statement Model'!H4 -> 0.35624305 | G8: =G7/'T-Mobile 3 Statement Model'!I4 -> 0.35624305 | H8: =H7/'T-Mobile 3 Statement Model'!J4 -> 0.35624305
B10: D&A | C10: ='T-Mobile 3 Statement Model'!E23 -> -13508 | D10: ='T-Mobile 3 Statement Model'!F23 -> -14325.6 | E10: ='T-Mobile 3 Statement Model'!G23 -> -15192.688 | F10: ='T-Mobile 3 Statement Model'!H23 -> -16112.257 | G10: ='T-Mobile 3 Statement Model'!I23 -> -17087.486 | H10: ='T-Mobile 3 Statement Model'!J23 -> -18121.742
B11: EBIT | C11: ='T-Mobile 3 Statement Model'!E7 -> 18279 | D11: ='T-Mobile 3 Statement Model'!F7 -> 19038.018 | E11: ='T-Mobile 3 Statement Model'!G7 -> 20190.335 | F11: ='T-Mobile 3 Statement Model'!H7 -> 21412.397 | G11: ='T-Mobile 3 Statement Model'!I7 -> 22708.428 | H11: ='T-Mobile 3 Statement Model'!J7 -> 24082.904
B13: Free Cash Flow
B14: EBITDA | C14: =C7 -> 31787 | D14: =D7 -> 33363.619 | E14: =E7 -> 35383.022 | F14: =F7 -> 37524.655 | G14: =G7 -> 39795.914 | H14: =H7 -> 42204.646
B15: Unlevered Taxes | C15: =-(C11*$F$39) -> -4285.9074 | D15: =-(D11*$F$39) -> -4463.8757 | E15: =-(E11*$F$39) -> -4734.0612 | F15: =-(F11*$F$39) -> -5020.6003 | G15: =-(G11*$F$39) -> -5324.4828 | H15: =-(H11*$F$39) -> -5646.7584
B16: PP&E CapEx | C16: ='T-Mobile 3 Statement Model'!E25 -> -9955 | D16: ='T-Mobile 3 Statement Model'!F25 -> -10557.547 | E16: ='T-Mobile 3 Statement Model'!G25 -> -11196.565 | F16: ='T-Mobile 3 Statement Model'!H25 -> -11874.261 | G16: ='T-Mobile 3 Statement Model'!I25 -> -12592.976 | H16: ='T-Mobile 3 Statement Model'!J25 -> -13355.193
B17: Intangibles CapEx | C17: ='T-Mobile 3 Statement Model'!E29 -> -2568 | D17: ='T-Mobile 3 Statement Model'!F29 -> -2723.4336 | E17: ='T-Mobile 3 Statement Model'!G29 -> -2888.2752 | F17: ='T-Mobile 3 Statement Model'!H29 -> -3063.0942 | G17: ='T-Mobile 3 Statement Model'!I29 -> -3248.4945 | H17: ='T-Mobile 3 Statement Model'!J29 -> -3445.1165
B18: Change In Operating Working Capital | C18: =-('T-Mobile 3 Statement Model'!E98-'T-Mobile 3 Statement Model'!D98) -> -2597 | D18: =-('T-Mobile 3 Statement Model'!F98-'T-Mobile 3 Statement Model'!E98) -> -38.98718 | E18: =-('T-Mobile 3 Statement Model'!G98-'T-Mobile 3 Statement Model'!F98) -> -42.368209 | F18: =-('T-Mobile 3 Statement Model'!H98-'T-Mobile 3 Statement Model'!G98) -> -44.932634 | G18: =-('T-Mobile 3 Statement Model'!I98-'T-Mobile 3 Statement Model'!H98) -> -47.652277 | H18: =-('T-Mobile 3 Statement Model'!J98-'T-Mobile 3 Statement Model'!I98) -> -50.536533
B19: Unlevered Free Cash Flow | C19: =SUM(C14:C18) -> 12381.093 | D19: =SUM(D14:D18) -> 15579.775 | E19: =SUM(E14:E18) -> 16521.752 | F19: =SUM(F14:F18) -> 17521.766 | G19: =SUM(G14:G18) -> 18582.308 | H19: =SUM(H14:H18) -> 19707.042
B21: Discounted Cash Flow
B22: Unlevered Free Cash Flow | D22: =D19 -> 15579.775 | E22: =E19 -> 16521.752 | F22: =F19 -> 17521.766 | G22: =G19 -> 18582.308 | H22: =H19 -> 19707.042
B23: Terminal Value | H23: =H14*C43 -> 295432.52
B24: Total Unlevered Free Cash Flow | D24: =SUM(D22:D23) -> 15579.775 | E24: =SUM(E22:E23) -> 16521.752 | F24: =SUM(F22:F23) -> 17521.766 | G24: =SUM(G22:G23) -> 18582.308 | H24: =SUM(H22:H23) -> 315139.57
B26: Present Value UFCF | C26: =SUM(D26:H26) -> 296097.32 | D26: =D24/((1+$C$45)^D2) -> 14717.535 | E26: =E24/((1+$C$45)^E2) -> 14743.614 | F26: =F24/((1+$C$45)^F2) -> 14770.651 | G26: =G24/((1+$C$45)^G2) -> 14797.738 | H26: =H24/((1+$C$45)^H2) -> 237067.78
B27: Net Present Value | C27: =NPV(C45,D24:H24) -> 296097.32
B29: Enterprise Value to Equity Value | E29: WACC Schedule
B30: PV of Explicit Forecast UFCF | C30: =SUM(D26:H26)-C31 -> 73854.414 | E30: Share Price (10/13/2026) | F30: 154.06
B31: PV of Terminal Value | C31: =H23/((1+$C$45)^H2) -> 222242.91 | E31: Shares Outstanding | F31: =1101862739/1000000 -> 1101.8627
B32: Enterprise Value | C32: =C30+C31 -> 296097.32 | E32: Market Capitalization | F32: =F30*F31 -> 169752.97
B33: Cash & Cash Equivalents | C33: ='T-Mobile 3 Statement Model'!E42 -> 5598 | E33: Total Debt | F33: =('T-Mobile 3 Statement Model'!E59+'T-Mobile 3 Statement Model'!E66+'T-Mobile 3 Statement Model'!E67) -> 92084
B34: Total Debt & Obligations | C34: =-('T-Mobile 3 Statement Model'!E59+'T-Mobile 3 Statement Model'!E66+'T-Mobile 3 Statement Model'!E67) -> -92084 | E34: Total Capital | F34: =F32+F33 -> 261836.97
E35: Weight of Equity | F35: =F32/F34 -> 0.64831552
B36: Implied Equity Value | C36: =SUM(C32:C35) -> 209611.32 | E36: Weight of Debt | F36: =F33/F34 -> 0.35168448
B37: Diluted Shares Outstanding | C37: =F31 -> 1101.8627
B38: Implied Share Price | C38: =C36/C37 -> 190.23361 | E38: Pre-Tax Cost of Debt | F38: ='T-Mobile 3 Statement Model'!F37 -> 0.042
B39: Current Share Price | C39: =F30 -> 154.06 | E39: Marginal Tax Rate | F39: ='T-Mobile 3 Statement Model'!F20 -> 0.23447166
B40: Implied Premium (Discount) | C40: =(C38/C39)-1 -> 0.23480206 | E40: After-Tax Cost of Debt | F40: =F38*(1-F39) -> 0.03215219
E42: Risk Free Rate | F42: 0.043
B43: Terminal Multiple | C43: 7 | E43: Equity Beta | F43: 0.63
E44: Equity Risk Premium | F44: 0.0475
B45: WACC | C45: =(F35*F45)+(F36*F40) -> 0.058585836 | E45: Cost of Equity | F45: =F42+(F43*F44) -> 0.072925
B48: Sensitivity Table
B49: =C38 -> 190.23361 | C49: 6 | D49: 6.5 | E49: 7 | F49: 7.5 | G49: 8
B50: 0.045 | C50: 175.61708 | D50: 190.98522 | E50: 206.35336 | F50: 221.7215 | G50: 237.08964
...
